Workbook
Name cal.year: Customizations!$C$4
Name holiday_dates: holidays[Date]
Name icon_types: icons[Type]
Name month.nums: Calc!$C$13:$C$84
Name monthly.calendar: Calc!$D$13:$J$84
Name months.list: _xlfn.ANCHORARRAY(Calc!$V$13)
Name planner_dates: Plan[Date]
Name show.planner: Customizations!$C$7
Name week.start: Customizations!$C$5
Name weekend.type: Customizations!$C$6

Sheet Calendar
C1: Calendar & Planner Template (2026)
C4: =cal.year&" Calendar" -> 2026 Calendar | AI4: Upcoming Activities
C6: 1 | D6: =TEXT(C9,"MMMM") -> #NAME? | K6: 2 | L6: =TEXT(K9,"MMMM") -> #NAME? | S6: 3 | T6: =TEXT(S9,"MMMM") -> #NAME? | AA6: 4 | AB6: =TEXT(AA9,"MMMM") -> #NAME? | AI6: =Calc!R13 -> #NAME? | AJ6: =Calc!S13 -> No upcoming activities
C7: =LEFT(TEXT(C9,"DDD"),1) -> #NAME? | D7: =LEFT(TEXT(D9,"DDD"),1) -> #NAME? | E7: =LEFT(TEXT(E9,"DDD"),1) -> #NAME? | F7: =LEFT(TEXT(F9,"DDD"),1) -> #NAME? | G7: =LEFT(TEXT(G9,"DDD"),1) -> #NAME? | H7: =LEFT(TEXT(H9,"DDD"),1) -> #NAME? | I7: =LEFT(TEXT(I9,"DDD"),1) -> #NAME? | K7: =LEFT(TEXT(K9,"DDD"),1) -> #NAME? | L7: =LEFT(TEXT(L9,"DDD"),1) -> #NAME? | M7: =LEFT(TEXT(M9,"DDD"),1) -> #NAME? | N7: =LEFT(TEXT(N9,"DDD"),1) -> #NAME? | O7: =LEFT(TEXT(O9,"DDD"),1) -> #NAME? | P7: =LEFT(TEXT(P9,"DDD"),1) -> #NAME? | Q7: =LEFT(TEXT(Q9,"DDD"),1) -> #NAME? | S7: =LEFT(TEXT(S9,"DDD"),1) -> #NAME? | T7: =LEFT(TEXT(T9,"DDD"),1) -> #NAME? | U7: =LEFT(TEXT(U9,"DDD"),1) -> #NAME? | V7: =LEFT(TEXT(V9,"DDD"),1) -> #NAME? | W7: =LEFT(TEXT(W9,"DDD"),1) -> #NAME? | X7: =LEFT(TEXT(X9,"DDD"),1) -> #NAME? | Y7: =LEFT(TEXT(Y9,"DDD"),1) -> #NAME? | AA7: =LEFT(TEXT(AA9,"DDD"),1) -> #NAME? | AB7: =LEFT(TEXT(AB9,"DDD"),1) -> #NAME? | AC7: =LEFT(TEXT(AC9,"DDD"),1) -> #NAME? | AD7: =LEFT(TEXT(AD9,"DDD"),1) -> #NAME? | AE7: =LEFT(TEXT(AE9,"DDD"),1) -> #NAME? | AF7: =LEFT(TEXT(AF9,"DDD"),1) -> #NAME? | AG7: =LEFT(TEXT(AG9,"DDD"),1) -> #NAME? | AI7: =Calc!R14 -> #NAME? | AJ7: =Calc!S14 -> #NAME?
C8: {=_xlfn.LET(_xlpm.dt, _xlfn._xlws.FILTER(monthly.calendar, month.nums=C6), IF(MONTH(_xlpm.dt)<>C6,"",_xlpm.dt))} -> #NAME? | D8: #NAME? | E8: #NAME? | F8: #NAME? | G8: #NAME? | H8: #NAME? | I8: #NAME? | K8: {=_xlfn.LET(_xlpm.dt, _xlfn._xlws.FILTER(monthly.calendar, month.nums=K6), IF(MONTH(_xlpm.dt)<>K6,"",_xlpm.dt))} -> #NAME? | L8: #NAME? | M8: #NAME? | N8: #NAME? | O8: #NAME? | P8: #NAME? | Q8: #NAME? | S8: {=_xlfn.LET(_xlpm.dt, _xlfn._xlws.FILTER(monthly.calendar, month.nums=S6), IF(MONTH(_xlpm.dt)<>S6,"",_xlpm.dt))} -> #NAME? | T8: #NAME? | U8: #NAME? | V8: #NAME? | W8: #NAME? | X8: #NAME? | Y8: #NAME? | AA8: {=_xlfn.LET(_xlpm.dt, _xlfn._xlws.FILTER(monthly.calendar, month.nums=AA6), IF(MONTH(_xlpm.dt)<>AA6,"",_xlpm.dt))} -> #NAME? | AB8: #NAME? | AC8: #NAME? | AD8: #NAME? | AE8: #NAME? | AF8: #NAME? | AG8: #NAME? | AI8: =Calc!R15 -> #NAME? | AJ8: =Calc!S15 -> #NAME?
C9: #NAME? | D9: #NAME? | E9: #NAME? | F9: #NAME? | G9: #NAME? | H9: #NAME? | I9: #NAME? | K9: #NAME? | L9: #NAME? | M9: #NAME? | N9: #NAME? | O9: #NAME? | P9: #NAME? | Q9: #NAME? | S9: #NAME? | T9: #NAME? | U9: #NAME? | V9: #NAME? | W9: #NAME? | X9: #NAME? | Y9: #NAME? | AA9: #NAME? | AB9: #NAME? | AC9: #NAME? | AD9: #NAME? | AE9: #NAME? | AF9: #NAME? | AG9: #NAME? | AI9: =Calc!R16 -> #NAME? | AJ9: =Calc!S16 -> #NAME?
C10: #NAME? | D10: #NAME? | E10: #NAME? | F10: #NAME? | G10: #NAME? | H10: #NAME? | I10: #NAME? | K10: #NAME? | L10: #NAME? | M10: #NAME? | N10: #NAME? | O10: #NAME? | P10: #NAME? | Q10: #NAME? | S10: #NAME? | T10: #NAME? | U10: #NAME? | V10: #NAME? | W10: #NAME? | X10: #NAME? | Y10: #NAME? | AA10: #NAME? | AB10: #NAME? | AC10: #NAME? | AD10: #NAME? | AE10: #NAME? | AF10: #NAME? | AG10: #NAME? | AI10: =Calc!R17 -> #NAME? | AJ10: =Calc!S17 -> #NAME?
C11: #NAME? | D11: #NAME? | E11: #NAME? | F11: #NAME? | G11: #NAME? | H11: #NAME? | I11: #NAME? | K11: #NAME? | L11: #NAME? | M11: #NAME? | N11: #NAME? | O11: #NAME? | P11: #NAME? | Q11: #NAME? | S11: #NAME? | T11: #NAME? | U11: #NAME? | V11: #NAME? | W11: #NAME? | X11: #NAME? | Y11: #NAME? | AA11: #NAME? | AB11: #NAME? | AC11: #NAME? | AD11: #NAME? | AE11: #NAME? | AF11: #NAME? | AG11: #NAME? | AI11: =Calc!R18 -> #NAME? | AJ11: =Calc!S18 -> #NAME?
C12: #NAME? | D12: #NAME? | E12: #NAME? | F12: #NAME? | G12: #NAME? | H12: #NAME? | I12: #NAME? | K12: #NAME? | L12: #NAME? | M12: #NAME? | N12: #NAME? | O12: #NAME? | P12: #NAME? | Q12: #NAME? | S12: #NAME? | T12: #NAME? | U12: #NAME? | V12: #NAME? | W12: #NAME? | X12: #NAME? | Y12: #NAME? | AA12: #NAME? | AB12: #NAME? | AC12: #NAME? | AD12: #NAME? | AE12: #NAME? | AF12: #NAME? | AG12: #NAME? | AI12: =Calc!R19 -> #NAME? | AJ12: =Calc!S19 -> #NAME?
C13: #NAME? | D13: #NAME? | E13: #NAME? | F13: #NAME? | G13: #NAME? | H13: #NAME? | I13: #NAME? | K13: #NAME? | L13: #NAME? | M13: #NAME? | N13: #NAME? | O13: #NAME? | P13: #NAME? | Q13: #NAME? | S13: #NAME? | T13: #NAME? | U13: #NAME? | V13: #NAME? | W13: #NAME? | X13: #NAME? | Y13: #NAME? | AA13: #NAME? | AB13: #NAME? | AC13: #NAME? | AD13: #NAME? | AE13: #NAME? | AF13: #NAME? | AG13: #NAME? | AI13: =Calc!R20 -> #NAME? | AJ13: =Calc!S20 -> #NAME?
AI14: =Calc!R21 -> #NAME? | AJ14: =Calc!S21 -> #NAME?
C15: 5 | D15: =TEXT(C18,"MMMM") -> #NAME? | K15: 6 | L15: =TEXT(K18,"MMMM") -> #NAME? | S15: 7 | T15: =TEXT(S18,"MMMM") -> #NAME? | AA15: 8 | AB15: =TEXT(AA18,"MMMM") -> #NAME? | AI15: =Calc!R22 -> #NAME? | AJ15: =Calc!S22 -> #NAME?
C16: =LEFT(TEXT(C18,"DDD"),1) -> #NAME? | D16: =LEFT(TEXT(D18,"DDD"),1) -> #NAME? | E16: =LEFT(TEXT(E18,"DDD"),1) -> #NAME? | F16: =LEFT(TEXT(F18,"DDD"),1) -> #NAME? | G16: =LEFT(TEXT(G18,"DDD"),1) -> #NAME? | H16: =LEFT(TEXT(H18,"DDD"),1) -> #NAME? | I16: =LEFT(TEXT(I18,"DDD"),1) -> #NAME? | K16: =LEFT(TEXT(K18,"DDD"),1) -> #NAME? | L16: =LEFT(TEXT(L18,"DDD"),1) -> #NAME? | M16: =LEFT(TEXT(M18,"DDD"),1) -> #NAME? | N16: =LEFT(TEXT(N18,"DDD"),1) -> #NAME? | O16: =LEFT(TEXT(O18,"DDD"),1) -> #NAME? | P16: =LEFT(TEXT(P18,"DDD"),1) -> #NAME? | Q16: =LEFT(TEXT(Q18,"DDD"),1) -> #NAME? | S16: =LEFT(TEXT(S18,"DDD"),1) -> #NAME? | T16: =LEFT(TEXT(T18,"DDD"),1) -> #NAME? | U16: =LEFT(TEXT(U18,"DDD"),1) -> #NAME? | V16: =LEFT(TEXT(V18,"DDD"),1) -> #NAME? | W16: =LEFT(TEXT(W18,"DDD"),1) -> #NAME? | X16: =LEFT(TEXT(X18,"DDD"),1) -> #NAME? | Y16: =LEFT(TEXT(Y18,"DDD"),1) -> #NAME? | AA16: =LEFT(TEXT(AA18,"DDD"),1) -> #NAME? | AB16: =LEFT(TEXT(AB18,"DDD"),1) -> #NAME? | AC16: =LEFT(TEXT(AC18,"DDD"),1) -> #NAME? | AD16: =LEFT(TEXT(AD18,"DDD"),1) -> #NAME? | AE16: =LEFT(TEXT(AE18,"DDD"),1) -> #NAME? | AF16: =LEFT(TEXT(AF18,"DDD"),1) -> #NAME? | AG16: =LEFT(TEXT(AG18,"DDD"),1) -> #NAME? | AI16: =Calc!R23 -> #NAME? | AJ16: =Calc!S23 -> #NAME?
C17: {=_xlfn.LET(_xlpm.dt, _xlfn._xlws.FILTER(monthly.calendar, month.nums=C15), IF(MONTH(_xlpm.dt)<>C15,"",_xlpm.dt))} -> #NAME? | D17: #NAME? | E17: #NAME? | F17: #NAME? | G17: #NAME? | H17: #NAME? | I17: #NAME? | K17: {=_xlfn.LET(_xlpm.dt, _xlfn._xlws.FILTER(monthly.calendar, month.nums=K15), IF(MONTH(_xlpm.dt)<>K15,"",_xlpm.dt))} -> #NAME? | L17: #NAME? | M17: #NAME? | N17: #NAME? | O17: #NAME? | P17: #NAME? | Q17: #NAME? | S17: {=_xlfn.LET(_xlpm.dt, _xlfn._xlws.FILTER(monthly.calendar, month.nums=S15), IF(MONTH(_xlpm.dt)<>S15,"",_xlpm.dt))} -> #NAME? | T17: #NAME? | U17: #NAME? | V17: #NAME? | W17: #NAME? | X17: #NAME? | Y17: #NAME? | AA17: {=_xlfn.LET(_xlpm.dt, _xlfn._xlws.FILTER(monthly.calendar, month.nums=AA15), IF(MONTH(_xlpm.dt)<>AA15,"",_xlpm.dt))} -> #NAME? | AB17: #NAME? | AC17: #NAME? | AD17: #NAME? | AE17: #NAME? | AF17: #NAME? | AG17: #NAME? | AI17: =Calc!R24 -> #NAME? | AJ17: =Calc!S24 -> #NAME?
C18: #NAME? | D18: #NAME? | E18: #NAME? | F18: #NAME? | G18: #NAME? | H18: #NAME? | I18: #NAME? | K18: #NAME? | L18: #NAME? | M18: #NAME? | N18: #NAME? | O18: #NAME? | P18: #NAME? | Q18: #NAME? | S18: #NAME? | T18: #NAME? | U18: #NAME? | V18: #NAME? | W18: #NAME? | X18: #NAME? | Y18: #NAME? | AA18: #NAME? | AB18: #NAME? | AC18: #NAME? | AD18: #NAME? | AE18: #NAME? | AF18: #NAME? | AG18: #NAME? | AI18: =Calc!R25 -> #NAME? | AJ18: =Calc!S25 -> #NAME?
C19: #NAME? | D19: #NAME? | E19: #NAME? | F19: #NAME? | G19: #NAME? | H19: #NAME? | I19: #NAME? | K19: #NAME? | L19: #NAME? | M19: #NAME? | N19: #NAME? | O19: #NAME? | P19: #NAME? | Q19: #NAME? | S19: #NAME? | T19: #NAME? | U19: #NAME? | V19: #NAME? | W19: #NAME? | X19: #NAME? | Y19: #NAME? | AA19: #NAME? | AB19: #NAME? | AC19: #NAME? | AD19: #NAME? | AE19: #NAME? | AF19: #NAME? | AG19: #NAME? | AI19: =Calc!R26 -> #NAME? | AJ19: =Calc!S26 -> #NAME?
C20: #NAME? | D20: #NAME? | E20: #NAME? | F20: #NAME? | G20: #NAME? | H20: #NAME? | I20: #NAME? | K20: #NAME? | L20: #NAME? | M20: #NAME? | N20: #NAME? | O20: #NAME? | P20: #NAME? | Q20: #NAME? | S20: #NAME? | T20: #NAME? | U20: #NAME? | V20: #NAME? | W20: #NAME? | X20: #NAME? | Y20: #NAME? | AA20: #NAME? | AB20: #NAME? | AC20: #NAME? | AD20: #NAME? | AE20: #NAME? | AF20: #NAME? | AG20: #NAME? | AI20: =Calc!R27 -> #NAME? | AJ20: =Calc!S27 -> #NAME?
C21: #NAME? | D21: #NAME? | E21: #NAME? | F21: #NAME? | G21: #NAME? | H21: #NAME? | I21: #NAME? | K21: #NAME? | L21: #NAME? | M21: #NAME? | N21: #NAME? | O21: #NAME? | P21: #NAME? | Q21: #NAME? | S21: #NAME? | T21: #NAME? | U21: #NAME? | V21: #NAME? | W21: #NAME? | X21: #NAME? | Y21: #NAME? | AA21: #NAME? | AB21: #NAME? | AC21: #NAME? | AD21: #NAME? | AE21: #NAME? | AF21: #NAME? | AG21: #NAME? | AI21: =Calc!R28 | AJ21: =Calc!S28
C22: #NAME? | D22: #NAME? | E22: #NAME? | F22: #NAME? | G22: #NAME? | H22: #NAME? | I22: #NAME? | K22: #NAME? | L22: #NAME? | M22: #NAME? | N22: #NAME? | O22: #NAME? | P22: #NAME? | Q22: #NAME? | S22: #NAME? | T22: #NAME? | U22: #NAME? | V22: #NAME? | W22: #NAME? | X22: #NAME? | Y22: #NAME? | AA22: #NAME? | AB22: #NAME? | AC22: #NAME? | AD22: #NAME? | AE22: #NAME? | AF22: #NAME? | AG22: #NAME? | AI22: =Calc!R29 | AJ22: =Calc!S29
AI23: =Calc!R30 | AJ23: =Calc!S30
C24: 9 | D24: =TEXT(C27,"MMMM") -> #NAME? | K24: 10 | L24: =TEXT(K27,"MMMM") -> #NAME? | S24: 11 | T24: =TEXT(S27,"MMMM") -> #NAME? | AA24: 12 | AB24: =TEXT(AA27,"MMMM") -> #NAME? | AI24: =Calc!R31 | AJ24: =Calc!S31
C25: =LEFT(TEXT(C27,"DDD"),1) -> #NAME? | D25: =LEFT(TEXT(D27,"DDD"),1) -> #NAME? | E25: =LEFT(TEXT(E27,"DDD"),1) -> #NAME? | F25: =LEFT(TEXT(F27,"DDD"),1) -> #NAME? | G25: =LEFT(TEXT(G27,"DDD"),1) -> #NAME? | H25: =LEFT(TEXT(H27,"DDD"),1) -> #NAME? | I25: =LEFT(TEXT(I27,"DDD"),1) -> #NAME? | K25: =LEFT(TEXT(K27,"DDD"),1) -> #NAME? | L25: =LEFT(TEXT(L27,"DDD"),1) -> #NAME? | M25: =LEFT(TEXT(M27,"DDD"),1) -> #NAME? | N25: =LEFT(TEXT(N27,"DDD"),1) -> #NAME? | O25: =LEFT(TEXT(O27,"DDD"),1) -> #NAME? | P25: =LEFT(TEXT(P27,"DDD"),1) -> #NAME? | Q25: =LEFT(TEXT(Q27,"DDD"),1) -> #NAME? | S25: =LEFT(TEXT(S27,"DDD"),1) -> #NAME? | T25: =LEFT(TEXT(T27,"DDD"),1) -> #NAME? | U25: =LEFT(TEXT(U27,"DDD"),1) -> #NAME? | V25: =LEFT(TEXT(V27,"DDD"),1) -> #NAME? | W25: =LEFT(TEXT(W27,"DDD"),1) -> #NAME? | X25: =LEFT(TEXT(X27,"DDD"),1) -> #NAME? | Y25: =LEFT(TEXT(Y27,"DDD"),1) -> #NAME? | AA25: =LEFT(TEXT(AA27,"DDD"),1) -> #NAME? | AB25: =LEFT(TEXT(AB27,"DDD"),1) -> #NAME? | AC25: =LEFT(TEXT(AC27,"DDD"),1) -> #NAME? | AD25: =LEFT(TEXT(AD27,"DDD"),1) -> #NAME? | AE25: =LEFT(TEXT(AE27,"DDD"),1) -> #NAME? | AF25: =LEFT(TEXT(AF27,"DDD"),1) -> #NAME? | AG25: =LEFT(TEXT(AG27,"DDD"),1) -> #NAME? | AI25: =Calc!R32 | AJ25: =Calc!S32
C26: {=_xlfn.LET(_xlpm.dt, _xlfn._xlws.FILTER(monthly.calendar, month.nums=C24), IF(MONTH(_xlpm.dt)<>C24,"",_xlpm.dt))} -> #NAME? | D26: #NAME? | E26: #NAME? | F26: #NAME? | G26: #NAME? | H26: #NAME? | I26: #NAME? | K26: {=_xlfn.LET(_xlpm.dt, _xlfn._xlws.FILTER(monthly.calendar, month.nums=K24), IF(MONTH(_xlpm.dt)<>K24,"",_xlpm.dt))} -> #NAME? | L26: #NAME? | M26: #NAME? | N26: #NAME? | O26: #NAME? | P26: #NAME? | Q26: #NAME? | S26: {=_xlfn.LET(_xlpm.dt, _xlfn._xlws.FILTER(monthly.calendar, month.nums=S24), IF(MONTH(_xlpm.dt)<>S24,"",_xlpm.dt))} -> #NAME? | T26: #NAME? | U26: #NAME? | V26: #NAME? | W26: #NAME? | X26: #NAME? | Y26: #NAME? | AA26: {=_xlfn.LET(_xlpm.dt, _xlfn._xlws.FILTER(monthly.calendar, month.nums=AA24), IF(MONTH(_xlpm.dt)<>AA24,"",_xlpm.dt))} -> #NAME? | AB26: #NAME? | AC26: #NAME? | AD26: #NAME? | AE26: #NAME? | AF26: #NAME? | AG26: #NAME? | AI26: =Calc!R33 | AJ26: =Calc!S33
C27: #NAME? | D27: #NAME? | E27: #NAME? | F27: #NAME? | G27: #NAME? | H27: #NAME? | I27: #NAME? | K27: #NAME? | L27: #NAME? | M27: #NAME? | N27: #NAME? | O27: #NAME? | P27: #NAME? | Q27: #NAME? | S27: #NAME? | T27: #NAME? | U27: #NAME? | V27: #NAME? | W27: #NAME? | X27: #NAME? | Y27: #NAME? | AA27: #NAME? | AB27: #NAME? | AC27: #NAME? | AD27: #NAME? | AE27: #NAME? | AF27: #NAME? | AG27: #NAME? | AI27: =Calc!R34 | AJ27: =Calc!S34
C28: #NAME? | D28: #NAME? | E28: #NAME? | F28: #NAME? | G28: #NAME? | H28: #NAME? | I28: #NAME? | K28: #NAME? | L28: #NAME? | M28: #NAME? | N28: #NAME? | O28: #NAME? | P28: #NAME? | Q28: #NAME? | S28: #NAME? | T28: #NAME? | U28: #NAME? | V28: #NAME? | W28: #NAME? | X28: #NAME? | Y28: #NAME? | AA28: #NAME? | AB28: #NAME? | AC28: #NAME? | AD28: #NAME? | AE28: #NAME? | AF28: #NAME? | AG28: #NAME? | AI28: =Calc!R35 | AJ28: =Calc!S35
C29: #NAME? | D29: #NAME? | E29: #NAME? | F29: #NAME? | G29: #NAME? | H29: #NAME? | I29: #NAME? | K29: #NAME? | L29: #NAME? | M29: #NAME? | N29: #NAME? | O29: #NAME? | P29: #NAME? | Q29: #NAME? | S29: #NAME? | T29: #NAME? | U29: #NAME? | V29: #NAME? | W29: #NAME? | X29: #NAME? | Y29: #NAME? | AA29: #NAME? | AB29: #NAME? | AC29: #NAME? | AD29: #NAME? | AE29: #NAME? | AF29: #NAME? | AG29: #NAME? | AI29: =Calc!R36 | AJ29: =Calc!S36
C30: #NAME? | D30: #NAME? | E30: #NAME? | F30: #NAME? | G30: #NAME? | H30: #NAME? | I30: #NAME? | K30: #NAME? | L30: #NAME? | M30: #NAME? | N30: #NAME? | O30: #NAME? | P30: #NAME? | Q30: #NAME? | S30: #NAME? | T30: #NAME? | U30: #NAME? | V30: #NAME? | W30: #NAME? | X30: #NAME? | Y30: #NAME? | AA30: #NAME? | AB30: #NAME? | AC30: #NAME? | AD30: #NAME? | AE30: #NAME? | AF30: #NAME? | AG30: #NAME? | AI30: =Calc!R37 | AJ30: =Calc!S37
C31: #NAME? | D31: #NAME? | E31: #NAME? | F31: #NAME? | G31: #NAME? | H31: #NAME? | I31: #NAME? | K31: #NAME? | L31: #NAME? | M31: #NAME? | N31: #NAME? | O31: #NAME? | P31: #NAME? | Q31: #NAME? | S31: #NAME? | T31: #NAME? | U31: #NAME? | V31: #NAME? | W31: #NAME? | X31: #NAME? | Y31: #NAME? | AA31: #NAME? | AB31: #NAME? | AC31: #NAME? | AD31: #NAME? | AE31: #NAME? | AF31: #NAME? | AG31: #NAME?

Sheet Any Month
C1: Any Month Calendar
C3: 4 | D3: ← Pick a month
C5: =TEXT(C9,"MMMM YYYY") -> #NAME?
C6: =UPPER(TEXT(C9,"DDD")) -> #NAME? | D6: =UPPER(TEXT(D9,"DDD")) -> #NAME? | E6: =UPPER(TEXT(E9,"DDD")) -> #NAME? | F6: =UPPER(TEXT(F9,"DDD")) -> #NAME? | G6: =UPPER(TEXT(G9,"DDD")) -> #NAME? | H6: =UPPER(TEXT(H9,"DDD")) -> #NAME? | I6: =UPPER(TEXT(I9,"DDD")) -> #NAME?
C7: =Calc!Z13 -> #NAME? | D7: =Calc!AA13 -> #NAME? | E7: =Calc!AB13 -> #NAME? | F7: =Calc!AC13 -> #NAME? | G7: =Calc!AD13 -> #NAME? | H7: =Calc!AE13 -> #NAME? | I7: =Calc!AF13 -> #NAME?
C8: =Calc!Z31 | D8: =Calc!AA31 | E8: =Calc!AB31 | F8: =Calc!AC31 | G8: =Calc!AD31 | H8: =Calc!AE31 | I8: =Calc!AF31
C9: =Calc!Z14 -> #NAME? | D9: =Calc!AA14 -> #NAME? | E9: =Calc!AB14 -> #NAME? | F9: =Calc!AC14 -> #NAME? | G9: =Calc!AD14 -> #NAME? | H9: =Calc!AE14 -> #NAME? | I9: =Calc!AF14 -> #NAME?
C10: =Calc!Z32 | D10: =Calc!AA32 | E10: =Calc!AB32 | F10: =Calc!AC32 | G10: =Calc!AD32 | H10: =Calc!AE32 | I10: =Calc!AF32
C11: =Calc!Z15 -> #NAME? | D11: =Calc!AA15 -> #NAME? | E11: =Calc!AB15 -> #NAME? | F11: =Calc!AC15 -> #NAME? | G11: =Calc!AD15 -> #NAME? | H11: =Calc!AE15 -> #NAME? | I11: =Calc!AF15 -> #NAME?
C12: =Calc!Z33 | D12: =Calc!AA33 | E12: =Calc!AB33 | F12: =Calc!AC33 | G12: =Calc!AD33 | H12: =Calc!AE33 | I12: =Calc!AF33
C13: =Calc!Z16 -> #NAME? | D13: =Calc!AA16 -> #NAME? | E13: =Calc!AB16 -> #NAME? | F13: =Calc!AC16 -> #NAME? | G13: =Calc!AD16 -> #NAME? | H13: =Calc!AE16 -> #NAME? | I13: =Calc!AF16 -> #NAME?
C14: =Calc!Z34 | D14: =Calc!AA34 | E14: =Calc!AB34 | F14: =Calc!AC34 | G14: =Calc!AD34 | H14: =Calc!AE34 | I14: =Calc!AF34
C15: =Calc!Z17 -> #NAME? | D15: =Calc!AA17 -> #NAME? | E15: =Calc!AB17 -> #NAME? | F15: =Calc!AC17 -> #NAME? | G15: =Calc!AD17 -> #NAME? | H15: =Calc!AE17 -> #NAME? | I15: =Calc!AF17 -> #NAME?
C16: =Calc!Z35 | D16: =Calc!AA35 | E16: =Calc!AB35 | F16: =Calc!AC35 | G16: =Calc!AD35 | H16: =Calc!AE35 | I16: =Calc!AF35
C17: =Calc!Z18 -> #NAME? | D17: =Calc!AA18 -> #NAME? | E17: =Calc!AB18 -> #NAME? | F17: =Calc!AC18 -> #NAME? | G17: =Calc!AD18 -> #NAME? | H17: =Calc!AE18 -> #NAME? | I17: =Calc!AF18 -> #NAME?
C18: =Calc!Z36 | D18: =Calc!AA36 | E18: =Calc!AB36 | F18: =Calc!AC36 | G18: =Calc!AD36 | H18: =Calc!AE36 | I18: =Calc!AF36

Sheet Printable 12 Month
C1: 12 Month Calendar (printable)
C5: =TEXT(C9,"MMMM YYYY") -> #NAME?
C6: =UPPER(TEXT(C9,"DDD")) -> #NAME? | D6: =UPPER(TEXT(D9,"DDD")) -> #NAME? | E6: =UPPER(TEXT(E9,"DDD")) -> #NAME? | F6: =UPPER(TEXT(F9,"DDD")) -> #NAME? | G6: =UPPER(TEXT(G9,"DDD")) -> #NAME? | H6: =UPPER(TEXT(H9,"DDD")) -> #NAME? | I6: =UPPER(TEXT(I9,"DDD")) -> #NAME?
C7: {=_xlfn.ANCHORARRAY(Calc!AS13)} -> #NAME? | D7: #NAME? | E7: #NAME? | F7: #NAME? | G7: #NAME? | H7: #NAME? | I7: #NAME?
C8: #NAME? | D8: #NAME? | E8: #NAME? | F8: #NAME? | G8: #NAME? | H8: #NAME? | I8: #NAME?
C9: #NAME? | D9: #NAME? | E9: #NAME? | F9: #NAME? | G9: #NAME? | H9: #NAME? | I9: #NAME?
C10: #NAME? | D10: #NAME? | E10: #NAME? | F10: #NAME? | G10: #NAME? | H10: #NAME? | I10: #NAME?
C11: #NAME? | D11: #NAME? | E11: #NAME? | F11: #NAME? | G11: #NAME? | H11: #NAME? | I11: #NAME?
C12: #NAME? | D12: #NAME? | E12: #NAME? | F12: #NAME? | G12: #NAME? | H12: #NAME? | I12: #NAME?
C13: #NAME? | D13: #NAME? | E13: #NAME? | F13: #NAME? | G13: #NAME? | H13: #NAME? | I13: #NAME?
C14: #NAME? | D14: #NAME? | E14: #NAME? | F14: #NAME? | G14: #NAME? | H14: #NAME? | I14: #NAME?
C15: #NAME? | D15: #NAME? | E15: #NAME? | F15: #NAME? | G15: #NAME? | H15: #NAME? | I15: #NAME?
C16: #NAME? | D16: #NAME? | E16: #NAME? | F16: #NAME? | G16: #NAME? | H16: #NAME? | I16: #NAME?
C17: #NAME? | D17: #NAME? | E17: #NAME? | F17: #NAME? | G17: #NAME? | H17: #NAME? | I17: #NAME?
C18: #NAME? | D18: #NAME? | E18: #NAME? | F18: #NAME? | G18: #NAME? | H18: #NAME? | I18: #NAME?
C21: =TEXT(C25,"MMMM YYYY") -> #NAME?
C22: =UPPER(TEXT(C25,"DDD")) -> #NAME? | D22: =UPPER(TEXT(D25,"DDD")) -> #NAME? | E22: =UPPER(TEXT(E25,"DDD")) -> #NAME? | F22: =UPPER(TEXT(F25,"DDD")) -> #NAME? | G22: =UPPER(TEXT(G25,"DDD")) -> #NAME? | H22: =UPPER(TEXT(H25,"DDD")) -> #NAME? | I22: =UPPER(TEXT(I25,"DDD")) -> #NAME?
C23: {=_xlfn.ANCHORARRAY(Calc!AS29)} -> #NAME? | D23: #NAME? | E23: #NAME? | F23: #NAME? | G23: #NAME? | H23: #NAME? | I23: #NAME?
C24: #NAME? | D24: #NAME? | E24: #NAME? | F24: #NAME? | G24: #NAME? | H24: #NAME? | I24: #NAME?
C25: #NAME? | D25: #NAME? | E25: #NAME? | F25: #NAME? | G25: #NAME? | H25: #NAME? | I25: #NAME?
C26: #NAME? | D26: #NAME? | E26: #NAME? | F26: #NAME? | G26: #NAME? | H26: #NAME? | I26: #NAME?
C27: #NAME? | D27: #NAME? | E27: #NAME? | F27: #NAME? | G27: #NAME? | H27: #NAME? | I27: #NAME?
C28: #NAME? | D28: #NAME? | E28: #NAME? | F28: #NAME? | G28: #NAME? | H28: #NAME? | I28: #NAME?
C29: #NAME? | D29: #NAME? | E29: #NAME? | F29: #NAME? | G29: #NAME? | H29: #NAME? | I29: #NAME?
C30: #NAME? | D30: #NAME? | E30: #NAME? | F30: #NAME? | G30: #NAME? | H30: #NAME? | I30: #NAME?
C31: #NAME? | D31: #NAME? | E31: #NAME? | F31: #NAME? | G31: #NAME? | H31: #NAME? | I31: #NAME?
C32: #NAME? | D32: #NAME? | E32: #NAME? | F32: #NAME? | G32: #NAME? | H32: #NAME? | I32: #NAME?
C33: #NAME? | D33: #NAME? | E33: #NAME? | F33: #NAME? | G33: #NAME? | H33: #NAME? | I33: #NAME?
C34: #NAME? | D34: #NAME? | E34: #NAME? | F34: #NAME? | G34: #NAME? | H34: #NAME? | I34: #NAME?
C37: =TEXT(C41,"MMMM YYYY") -> #NAME?
C38: =UPPER(TEXT(C41,"DDD")) -> #NAME? | D38: =UPPER(TEXT(D41,"DDD")) -> #NAME? | E38: =UPPER(TEXT(E41,"DDD")) -> #NAME? | F38: =UPPER(TEXT(F41,"DDD")) -> #NAME? | G38: =UPPER(TEXT(G41,"DDD")) -> #NAME? | H38: =UPPER(TEXT(H41,"DDD")) -> #NAME? | I38: =UPPER(TEXT(I41,"DDD")) -> #NAME?
C39: {=_xlfn.ANCHORARRAY(Calc!AS45)} -> #NAME? | D39: #NAME? | E39: #NAME? | F39: #NAME? | G39: #NAME? | H39: #NAME? | I39: #NAME?
C40: #NAME? | D40: #NAME? | E40: #NAME? | F40: #NAME? | G40: #NAME? | H40: #NAME? | I40: #NAME?
C41: #NAME? | D41: #NAME? | E41: #NAME? | F41: #NAME? | G41: #NAME? | H41: #NAME? | I41: #NAME?
C42: #NAME? | D42: #NAME? | E42: #NAME? | F42: #NAME? | G42: #NAME? | H42: #NAME? | I42: #NAME?
C43: #NAME? | D43: #NAME? | E43: #NAME? | F43: #NAME? | G43: #NAME? | H43: #NAME? | I43: #NAME?
C44: #NAME? | D44: #NAME? | E44: #NAME? | F44: #NAME? | G44: #NAME? | H44: #NAME? | I44: #NAME?
C45: #NAME? | D45: #NAME? | E45: #NAME? | F45: #NAME? | G45: #NAME? | H45: #NAME? | I45: #NAME?
C46: #NAME? | D46: #NAME? | E46: #NAME? | F46: #NAME? | G46: #NAME? | H46: #NAME? | I46: #NAME?
C47: #NAME? | D47: #NAME? | E47: #NAME? | F47: #NAME? | G47: #NAME? | H47: #NAME? | I47: #NAME?
...

Sheet Planner
C1: Set up your Planner here
C4: Date | D4: Activity | E4: Type
C5: 46038 | D5: Fly to Hong Kong | E5: Travel
C6: 46043 | D6: Wedding Anniversary | E6: Anniversaries
C7: 46048 | D7: Kids school re-opens | E7: Kids stuff
C8: 46059 | D8: Road Trip | E8: Travel
C9: 46067 | D9: Valentine Dinner | E9: Party
C10: 46082 | D10: House Insurance Renewal | E10: Home stuff
C11: 46084 | D11: Livestream | E11: Video
C12: 46122 | D12: Team Away Day | E12: Work stuff
C13: 46042 | D13: Train to Shenzhen | E13: Travel
C14: 46037 | D14: Meet Friend | E14: Party
C15: 46037 | D15: Call the Client | E15: Work stuff
C16: 46101 | D16: Fly to Seattle | E16: Travel
... C19: 46044 | D19: Return to Wellington | E19: Travel

Sheet Customizations
B1: Customizations
F3: Icon options | J3: Holiday List
B4: Year | C4: 2026 | D4: Change this to see calendar for another year | F4: Icon | G4: Type | J4: Date | K4: Holiday
B5: Week start | C5: 1 | D5: (1 for Monday, 7 for Sunday) | F5: 🎂 | G5: Anniversaries | J5: 46023 | K5: New Year's Day
B6: Weekend | C6: 1 | D6: (1 for Sat+Sun, 2 for Sun+Mon… 11 for Sun only, 12 for Mon only) | F6: ⏱ | G6: Appointment | J6: 46024 | K6: Day after New Year's Day
B7: Highlight Planner Dates? | C7: Yes | F7: 🏠 | G7: Home stuff | J7: 46041 | K7: Martin Luther King Jr. Birthday
F8: 🎉 | G8: Party | J8: 46048 | K8: Republic Day (India)
F9: ✈ | G9: Travel | J9: 46059 | K9: Waitangi Day
F10: 📺 | G10: Video | J10: 46069 | K10: President's Day
F11: 🏢 | G11: Work stuff | J11: 46085 | K11: Holi
F12: 👨‍👧‍👦 | G12: Kids stuff | J12: 46115 | K12: Good Friday
J13: 46118 | K13: Easter Monday
J14: 46139 | K14: ANZAC Day
J15: 46167 | K15: Memorial Day
J16: 46174 | K16: King's Birthday
J17: 46192 | K17: Juneteenth
J18: 46207 | K18: Independence Day
J19: 46213 | K19: Matariki
J20: 46272 | K20: Labor Day
J21: 46297 | K21: Gandhi Jayanti
J22: 46307 | K22: Columbus Day
J23: 46321 | K23: Labour Day (NZ)
J24: 46334 | K24: Diwali
... J29: 46249 | K29: Independence Day (India)

Sheet Calc
C1: Calculations - Do not edit
C8: 1 | E8: =DATE(cal.year,C8,1) -> 46023 | F8: 4 | H8: =E8 -> 46023 | N8: Today | O8: =TODAY() -> 46147
E9: prev. weekstart | H9: =E8-F8+1 -> 46020 | AJ9: All Months Printable Version | AS9: Interspersed for Printable version
N10: Next Activities | R10: For the Calendar (show only first 25) | V10: Month numbers (for drop down) | Z10: Selected Month | AA10: ='Any Month'!C3 -> 4
D12: =TEXT(D13,"DDD") -> #NAME? | E12: =TEXT(E13,"DDD") -> #NAME? | F12: =TEXT(F13,"DDD") -> #NAME? | G12: =TEXT(G13,"DDD") -> #NAME? | H12: =TEXT(H13,"DDD") -> #NAME? | I12: =TEXT(I13,"DDD") -> #NAME? | J12: =TEXT(J13,"DDD") -> #NAME? | K12: WEEKNUM | N12: Date | O12: Activity | P12: Type | R12: Type Icon | S12: Date & Activity | V12: Month | Z12: Calendar
C13: 1 | D13: {=_xlfn.LET(_xlpm.mStart, DATE(cal.year, C13, 1), _xlpm.wDay, WEEKDAY(_xlpm.mStart, 10+week.start), _xlfn.SEQUENCE(6,7,_xlpm.mStart-_xlpm.wDay+1))} -> #NAME? | E13: #NAME? | F13: #NAME? | G13: #NAME? | H13: #NAME? | I13: #NAME? | J13: #NAME? | K13: =WEEKNUM(D13,10+week.start) -> #NAME? | N13: {=_xlfn._xlws.SORT(_xlfn._xlws.FILTER(Plan[], Plan[Date]>=O8),1)} -> #NAME? | O13: #NAME? | P13: #NAME? | R13: =_xlfn.XLOOKUP(P13,icons[Type],icons[Icon],"") -> #NAME? | S13: =IFERROR(IF(N13=0,"",TEXT(N13,"d-mmm")&": "&O13),"No upcoming activities") -> No upcoming activities | V13: {=_xlfn.SEQUENCE(12)} -> 1 | Z13: {=_xlfn.LET(_xlpm.dt, _xlfn._xlws.FILTER(monthly.calendar, month.nums=AA10), IF(MONTH(_xlpm.dt)<>AA10,"",_xlpm.dt))} -> #NAME? | AA13: #NAME? | AB13: #NAME? | AC13: #NAME? | AD13: #NAME? | AE13: #NAME? | AF13: #NAME? | AI13: 1 | AJ13: {=_xlfn.LET(_xlpm.dt, _xlfn._xlws.FILTER(monthly.calendar, month.nums=AI13), IF(MONTH(_xlpm.dt)<>AI13,"",_xlpm.dt))} -> #NAME? | AK13: #NAME? | AL13: #NAME? | AM13: #NAME? | AN13: #NAME? | AO13: #NAME? | AP13: #NAME? | AS13: {=_xlfn.WRAPROWS(_xlfn.TOCOL(_xlfn.HSTACK(_xlfn.ANCHORARRAY(AJ13),_xlfn.ANCHORARRAY(AJ21))),7)} -> #NAME? | AT13: #NAME? | AU13: #NAME? | AV13: #NAME? | AW13: #NAME? | AX13: #NAME? | AY13: #NAME?
C14: =C13 -> 1 | D14: #NAME? | E14: #NAME? | F14: #NAME? | G14: #NAME? | H14: #NAME? | I14: #NAME? | J14: #NAME? | K14: =WEEKNUM(D14,10+week.start) -> #NAME? | N14: #NAME? | O14: #NAME? | P14: #NAME? | R14: =_xlfn.XLOOKUP(P14,icons[Type],icons[Icon],"") -> #NAME? | S14: =IF(N14=0,"",TEXT(N14,"d-mmm")&": "&O14) -> #NAME? | V14: 2 | Z14: #NAME? | AA14: #NAME? | AB14: #NAME? | AC14: #NAME? | AD14: #NAME? | AE14: #NAME? | AF14: #NAME? | AJ14: #NAME? | AK14: #NAME? | AL14: #NAME? | AM14: #NAME? | AN14: #NAME? | AO14: #NAME? | AP14: #NAME? | AS14: #NAME? | AT14: #NAME? | AU14: #NAME? | AV14: #NAME? | AW14: #NAME? | AX14: #NAME? | AY14: #NAME?
C15: =C14 -> 1 | D15: #NAME? | E15: #NAME? | F15: #NAME? | G15: #NAME? | H15: #NAME? | I15: #NAME? | J15: #NAME? | K15: =WEEKNUM(D15,10+week.start) -> #NAME? | N15: #NAME? | O15: #NAME? | P15: #NAME? | R15: =_xlfn.XLOOKUP(P15,icons[Type],icons[Icon],"") -> #NAME? | S15: =IF(N15=0,"",TEXT(N15,"d-mmm")&": "&O15) -> #NAME? | V15: 3 | Z15: #NAME? | AA15: #NAME? | AB15: #NAME? | AC15: #NAME? | AD15: #NAME? | AE15: #NAME? | AF15: #NAME? | AJ15: #NAME? | AK15: #NAME? | AL15: #NAME? | AM15: #NAME? | AN15: #NAME? | AO15: #NAME? | AP15: #NAME? | AS15: #NAME? | AT15: #NAME? | AU15: #NAME? | AV15: #NAME? | AW15: #NAME? | AX15: #NAME? | AY15: #NAME?
C16: =C15 -> 1 | D16: #NAME? | E16: #NAME? | F16: #NAME? | G16: #NAME? | H16: #NAME? | I16: #NAME? | J16: #NAME? | K16: =WEEKNUM(D16,10+week.start) -> #NAME? | N16: #NAME? | O16: #NAME? | P16: #NAME? | R16: =_xlfn.XLOOKUP(P16,icons[Type],icons[Icon],"") -> #NAME? | S16: =IF(N16=0,"",TEXT(N16,"d-mmm")&": "&O16) -> #NAME? | V16: 4 | Z16: #NAME? | AA16: #NAME? | AB16: #NAME? | AC16: #NAME? | AD16: #NAME? | AE16: #NAME? | AF16: #NAME? | AJ16: #NAME? | AK16: #NAME? | AL16: #NAME? | AM16: #NAME? | AN16: #NAME? | AO16: #NAME? | AP16: #NAME? | AS16: #NAME? | AT16: #NAME? | AU16: #NAME? | AV16: #NAME? | AW16: #NAME? | AX16: #NAME? | AY16: #NAME?
C17: =C16 -> 1 | D17: #NAME? | E17: #NAME? | F17: #NAME? | G17: #NAME? | H17: #NAME? | I17: #NAME? | J17: #NAME? | K17: =WEEKNUM(D17,10+week.start) -> #NAME? | N17: #NAME? | O17: #NAME? | P17: #NAME? | R17: =_xlfn.XLOOKUP(P17,icons[Type],icons[Icon],"") -> #NAME? | S17: =IF(N17=0,"",TEXT(N17,"d-mmm")&": "&O17) -> #NAME? | V17: 5 | Z17: #NAME? | AA17: #NAME? | AB17: #NAME? | AC17: #NAME? | AD17: #NAME? | AE17: #NAME? | AF17: #NAME? | AJ17: #NAME? | AK17: #NAME? | AL17: #NAME? | AM17: #NAME? | AN17: #NAME? | AO17: #NAME? | AP17: #NAME? | AS17: #NAME? | AT17: #NAME? | AU17: #NAME? | AV17: #NAME? | AW17: #NAME? | AX17: #NAME? | AY17: #NAME?
C18: =C17 -> 1 | D18: #NAME? | E18: #NAME? | F18: #NAME? | G18: #NAME? | H18: #NAME? | I18: #NAME? | J18: #NAME? | K18: =WEEKNUM(D18,10+week.start) -> #NAME? | N18: #NAME? | O18: #NAME? | P18: #NAME? | R18: =_xlfn.XLOOKUP(P18,icons[Type],icons[Icon],"") -> #NAME? | S18: =IF(N18=0,"",TEXT(N18,"d-mmm")&": "&O18) -> #NAME? | V18: 6 | Z18: #NAME? | AA18: #NAME? | AB18: #NAME? | AC18: #NAME? | AD18: #NAME? | AE18: #NAME? | AF18: #NAME? | AJ18: #NAME? | AK18: #NAME? | AL18: #NAME? | AM18: #NAME? | AN18: #NAME? | AO18: #NAME? | AP18: #NAME? | AS18: #NAME? | AT18: #NAME? | AU18: #NAME? | AV18: #NAME? | AW18: #NAME? | AX18: #NAME? | AY18: #NAME?
C19: =C13+1 -> 2 | D19: {=_xlfn.LET(_xlpm.mStart, DATE(cal.year, C19, 1), _xlpm.wDay, WEEKDAY(_xlpm.mStart, 10+week.start), _xlfn.SEQUENCE(6,7,_xlpm.mStart-_xlpm.wDay+1))} -> #NAME? | E19: #NAME? | F19: #NAME? | G19: #NAME? | H19: #NAME? | I19: #NAME? | J19: #NAME? | K19: =WEEKNUM(D19,10+week.start) -> #NAME? | N19: #NAME? | O19: #NAME? | P19: #NAME? | R19: =_xlfn.XLOOKUP(P19,icons[Type],icons[Icon],"") -> #NAME? | S19: =IF(N19=0,"",TEXT(N19,"d-mmm")&": "&O19) -> #NAME? | V19: 7 | AS19: #NAME? | AT19: #NAME? | AU19: #NAME? | AV19: #NAME? | AW19: #NAME? | AX19: #NAME? | AY19: #NAME?
C20: =C19 -> 2 | D20: #NAME? | E20: #NAME? | F20: #NAME? | G20: #NAME? | H20: #NAME? | I20: #NAME? | J20: #NAME? | K20: =WEEKNUM(D20,10+week.start) -> #NAME? | N20: #NAME? | O20: #NAME? | P20: #NAME? | R20: =_xlfn.XLOOKUP(P20,icons[Type],icons[Icon],"") -> #NAME? | S20: =IF(N20=0,"",TEXT(N20,"d-mmm")&": "&O20) -> #NAME? | V20: 8 | AS20: #NAME? | AT20: #NAME? | AU20: #NAME? | AV20: #NAME? | AW20: #NAME? | AX20: #NAME? | AY20: #NAME?
C21: =C20 -> 2 | D21: #NAME? | E21: #NAME? | F21: #NAME? | G21: #NAME? | H21: #NAME? | I21: #NAME? | J21: #NAME? | K21: =WEEKNUM(D21,10+week.start) -> #NAME? | N21: #NAME? | O21: #NAME? | P21: #NAME? | R21: =_xlfn.XLOOKUP(P21,icons[Type],icons[Icon],"") -> #NAME? | S21: =IF(N21=0,"",TEXT(N21,"d-mmm")&": "&O21) -> #NAME? | V21: 9 | Z21: Acts | AJ21: {=_xlfn.MAP(_xlfn.ANCHORARRAY(AJ13), _xlfn.LAMBDA(_xlpm.a, IFERROR(_xlfn.LET(_xlpm.events, _xlfn._xlws.FILTER(Plan[Activity],Plan[Date]=_xlpm.a), _xlpm.ic, _xlfn.XLOOKUP(_xlfn._xlws.FILTER(Plan[Type], Plan[Date]=_xlpm.a,"x"), icons[Type], icons[Icon]), _xlfn.TEXTJOIN(CHAR(10),TRUE, _xlpm.ic&_xlpm.events)),"")))} -> #NAME? | AK21: #NAME? | AL21: #NAME? | AM21: #NAME? | AN21: #NAME? | AO21: #NAME? | AP21: #NAME? | AS21: #NAME? | AT21: #NAME? | AU21: #NAME? | AV21: #NAME? | AW21: #NAME? | AX21: #NAME? | AY21: #NAME?
C22: =C21 -> 2 | D22: #NAME? | E22: #NAME? | F22: #NAME? | G22: #NAME? | H22: #NAME? | I22: #NAME? | J22: #NAME? | K22: =WEEKNUM(D22,10+week.start) -> #NAME? | N22: #NAME? | O22: #NAME? | P22: #NAME? | R22: =_xlfn.XLOOKUP(P22,icons[Type],icons[Icon],"") -> #NAME? | S22: =IF(N22=0,"",TEXT(N22,"d-mmm")&": "&O22) -> #NAME? | V22: 10 | Z22: {=IFERROR(_xlfn.XLOOKUP(_xlfn.MAP(_xlfn.ANCHORARRAY(Z13),_xlfn.LAMBDA(_xlpm.v, _xlfn._xlws.FILTER(Plan[Type],Plan[Date]=_xlpm.v,""))),icons[Type],icons[Icon])&" "&_xlfn.MAP(_xlfn.ANCHORARRAY(Z13),_xlfn.LAMBDA(_xlpm.v, _xlfn._xlws.FILTER(Plan[Activity],Plan[Date]=_xlpm.v,""))),"")} | AJ22: #NAME? | AK22: #NAME? | AL22: #NAME? | AM22: #NAME? | AN22: #NAME? | AO22: #NAME? | AP22: #NAME? | AS22: #NAME? | AT22: #NAME? | AU22: #NAME? | AV22: #NAME? | AW22: #NAME? | AX22: #NAME? | AY22: #NAME?
C23: =C22 -> 2 | D23: #NAME? | E23: #NAME? | F23: #NAME? | G23: #NAME? | H23: #NAME? | I23: #NAME? | J23: #NAME? | K23: =WEEKNUM(D23,10+week.start) -> #NAME? | N23: #NAME? | O23: #NAME? | P23: #NAME? | R23: =_xlfn.XLOOKUP(P23,icons[Type],icons[Icon],"") -> #NAME? | S23: =IF(N23=0,"",TEXT(N23,"d-mmm")&": "&O23) -> #NAME? | V23: 11 | AJ23: #NAME? | AK23: #NAME? | AL23: #NAME? | AM23: #NAME? | AN23: #NAME? | AO23: #NAME? | AP23: #NAME? | AS23: #NAME? | AT23: #NAME? | AU23: #NAME? | AV23: #NAME? | AW23: #NAME? | AX23: #NAME? | AY23: #NAME?
C24: =C23 -> 2 | D24: #NAME? | E24: #NAME? | F24: #NAME? | G24: #NAME? | H24: #NAME? | I24: #NAME? | J24: #NAME? | K24: =WEEKNUM(D24,10+week.start) -> #NAME? | N24: #NAME? | O24: #NAME? | P24: #NAME? | R24: =_xlfn.XLOOKUP(P24,icons[Type],icons[Icon],"") -> #NAME? | S24: =IF(N24=0,"",TEXT(N24,"d-mmm")&": "&O24) -> #NAME? | V24: 12 | AJ24: #NAME? | AK24: #NAME? | AL24: #NAME? | AM24: #NAME? | AN24: #NAME? | AO24: #NAME? | AP24: #NAME? | AS24: #NAME? | AT24: #NAME? | AU24: #NAME? | AV24: #NAME? | AW24: #NAME? | AX24: #NAME? | AY24: #NAME?
C25: =C19+1 -> 3 | D25: {=_xlfn.LET(_xlpm.mStart, DATE(cal.year, C25, 1), _xlpm.wDay, WEEKDAY(_xlpm.mStart, 10+week.start), _xlfn.SEQUENCE(6,7,_xlpm.mStart-_xlpm.wDay+1))} -> #NAME? | E25: #NAME? | F25: #NAME? | G25: #NAME? | H25: #NAME? | I25: #NAME? | J25: #NAME? | K25: =WEEKNUM(D25,10+week.start) -> #NAME? | N25: #NAME? | O25: #NAME? | P25: #NAME? | R25: =_xlfn.XLOOKUP(P25,icons[Type],icons[Icon],"") -> #NAME? | S25: =IF(N25=0,"",TEXT(N25,"d-mmm")&": "&O25) -> #NAME? | AJ25: #NAME? | AK25: #NAME? | AL25: #NAME? | AM25: #NAME? | AN25: #NAME? | AO25: #NAME? | AP25: #NAME?
C26: =C25 -> 3 | D26: #NAME? | E26: #NAME? | F26: #NAME? | G26: #NAME? | H26: #NAME? | I26: #NAME? | J26: #NAME? | K26: =WEEKNUM(D26,10+week.start) -> #NAME? | N26: #NAME? | O26: #NAME? | P26: #NAME? | R26: =_xlfn.XLOOKUP(P26,icons[Type],icons[Icon],"") -> #NAME? | S26: =IF(N26=0,"",TEXT(N26,"d-mmm")&": "&O26) -> #NAME? | AJ26: #NAME? | AK26: #NAME? | AL26: #NAME? | AM26: #NAME? | AN26: #NAME? | AO26: #NAME? | AP26: #NAME?
C27: =C26 -> 3 | D27: #NAME? | E27: #NAME? | F27: #NAME? | G27: #NAME? | H27: #NAME? | I27: #NAME? | J27: #NAME? | K27: =WEEKNUM(D27,10+week.start) -> #NAME? | N27: #NAME? | O27: #NAME? | P27: #NAME? | R27: =_xlfn.XLOOKUP(P27,icons[Type],icons[Icon],"") -> #NAME? | S27: =IF(N27=0,"",TEXT(N27,"d-mmm")&": "&O27) -> #NAME?
C28: =C27 -> 3 | D28: #NAME? | E28: #NAME? | F28: #NAME? | G28: #NAME? | H28: #NAME? | I28: #NAME? | J28: #NAME? | K28: =WEEKNUM(D28,10+week.start) -> #NAME? | R28: =_xlfn.XLOOKUP(P28,icons[Type],icons[Icon],"") | S28: =IF(N28=0,"",TEXT(N28,"d-mmm")&": "&O28)
C29: =C28 -> 3 | D29: #NAME? | E29: #NAME? | F29: #NAME? | G29: #NAME? | H29: #NAME? | I29: #NAME? | J29: #NAME? | K29: =WEEKNUM(D29,10+week.start) -> #NAME? | R29: =_xlfn.XLOOKUP(P29,icons[Type],icons[Icon],"") | S29: =IF(N29=0,"",TEXT(N29,"d-mmm")&": "&O29) | AI29: =AI13+1 -> 2 | AJ29: {=_xlfn.LET(_xlpm.dt, _xlfn._xlws.FILTER(monthly.calendar, month.nums=AI29), IF(MONTH(_xlpm.dt)<>AI29,"",_xlpm.dt))} -> #NAME? | AK29: #NAME? | AL29: #NAME? | AM29: #NAME? | AN29: #NAME? | AO29: #NAME? | AP29: #NAME? | AS29: {=_xlfn.WRAPROWS(_xlfn.TOCOL(_xlfn.HSTACK(_xlfn.ANCHORARRAY(AJ29),_xlfn.ANCHORARRAY(AJ37))),7)} -> #NAME? | AT29: #NAME? | AU29: #NAME? | AV29: #NAME? | AW29: #NAME? | AX29: #NAME? | AY29: #NAME?
C30: =C29 -> 3 | D30: #NAME? | E30: #NAME? | F30: #NAME? | G30: #NAME? | H30: #NAME? | I30: #NAME? | J30: #NAME? | K30: =WEEKNUM(D30,10+week.start) -> #NAME? | R30: =_xlfn.XLOOKUP(P30,icons[Type],icons[Icon],"") | S30: =IF(N30=0,"",TEXT(N30,"d-mmm")&": "&O30) | AJ30: #NAME? | AK30: #NAME? | AL30: #NAME? | AM30: #NAME? | AN30: #NAME? | AO30: #NAME? | AP30: #NAME? | AS30: #NAME? | AT30: #NAME? | AU30: #NAME? | AV30: #NAME? | AW30: #NAME? | AX30: #NAME? | AY30: #NAME?
C31: =C25+1 -> 4 | D31: {=_xlfn.LET(_xlpm.mStart, DATE(cal.year, C31, 1), _xlpm.wDay, WEEKDAY(_xlpm.mStart, 10+week.start), _xlfn.SEQUENCE(6,7,_xlpm.mStart-_xlpm.wDay+1))} -> #NAME? | E31: #NAME? | F31: #NAME? | G31: #NAME? | H31: #NAME? | I31: #NAME? | J31: #NAME? | K31: =WEEKNUM(D31,10+week.start) -> #NAME? | R31: =_xlfn.XLOOKUP(P31,icons[Type],icons[Icon],"") | S31: =IF(N31=0,"",TEXT(N31,"d-mmm")&": "&O31) | Z31: {=IFERROR(_xlfn.LET(_xlpm.events, _xlfn._xlws.FILTER(Plan[Activity],Plan[Date]=Calc!Z13), _xlpm.ic, _xlfn.XLOOKUP(_xlfn._xlws.FILTER(Plan[Type], Plan[Date]=Z13,"x"), icons[Type], icons[Icon]), _xlfn.TEXTJOIN(CHAR(10),TRUE, _xlpm.ic&_xlpm.events)),"")} | AA31: {=IFERROR(_xlfn.LET(_xlpm.events, _xlfn._xlws.FILTER(Plan[Activity],Plan[Date]=Calc!AA13), _xlpm.ic, _xlfn.XLOOKUP(_xlfn._xlws.FILTER(Plan[Type], Plan[Date]=AA13,"x"), icons[Type], icons[Icon]), _xlfn.TEXTJOIN(CHAR(10),TRUE, _xlpm.ic&_xlpm.events)),"")} | AB31: {=IFERROR(_xlfn.LET(_xlpm.events, _xlfn._xlws.FILTER(Plan[Activity],Plan[Date]=Calc!AB13), _xlpm.ic, _xlfn.XLOOKUP(_xlfn._xlws.FILTER(Plan[Type], Plan[Date]=AB13,"x"), icons[Type], icons[Icon]), _xlfn.TEXTJOIN(CHAR(10),TRUE, _xlpm.ic&_xlpm.events)),"")} | AC31: {=IFERROR(_xlfn.LET(_xlpm.events, _xlfn._xlws.FILTER(Plan[Activity],Plan[Date]=Calc!AC13), _xlpm.ic, _xlfn.XLOOKUP(_xlfn._xlws.FILTER(Plan[Type], Plan[Date]=AC13,"x"), icons[Type], icons[Icon]), _xlfn.TEXTJOIN(CHAR(10),TRUE, _xlpm.ic&_xlpm.events)),"")} | AD31: {=IFERROR(_xlfn.LET(_xlpm.events, _xlfn._xlws.FILTER(Plan[Activity],Plan[Date]=Calc!AD13), _xlpm.ic, _xlfn.XLOOKUP(_xlfn._xlws.FILTER(Plan[Type], Plan[Date]=AD13,"x"), icons[Type], icons[Icon]), _xlfn.TEXTJOIN(CHAR(10),TRUE, _xlpm.ic&_xlpm.events)),"")} | AE31: {=IFERROR(_xlfn.LET(_xlpm.events, _xlfn._xlws.FILTER(Plan[Activity],Plan[Date]=Calc!AE13), _xlpm.ic, _xlfn.XLOOKUP(_xlfn._xlws.FILTER(Plan[Type], Plan[Date]=AE13,"x"), icons[Type], icons[Icon]), _xlfn.TEXTJOIN(CHAR(10),TRUE, _xlpm.ic&_xlpm.events)),"")} | AF31: {=IFERROR(_xlfn.LET(_xlpm.events, _xlfn._xlws.FILTER(Plan[Activity],Plan[Date]=Calc!AF13), _xlpm.ic, _xlfn.XLOOKUP(_xlfn._xlws.FILTER(Plan[Type], Plan[Date]=AF13,"x"), icons[Type], icons[Icon]), _xlfn.TEXTJOIN(CHAR(10),TRUE, _xlpm.ic&_xlpm.events)),"")} | AJ31: #NAME? | AK31: #NAME? | AL31: #NAME? | AM31: #NAME? | AN31: #NAME? | AO31: #NAME? | AP31: #NAME? | AS31: #NAME? | AT31: #NAME? | AU31: #NAME? | AV31: #NAME? | AW31: #NAME? | AX31: #NAME? | AY31: #NAME?
C32: =C31 -> 4 | D32: #NAME? | E32: #NAME? | F32: #NAME? | G32: #NAME? | H32: #NAME? | I32: #NAME? | J32: #NAME? | K32: =WEEKNUM(D32,10+week.start) -> #NAME? | R32: =_xlfn.XLOOKUP(P32,icons[Type],icons[Icon],"") | S32: =IF(N32=0,"",TEXT(N32,"d-mmm")&": "&O32) | Z32: {=IFERROR(_xlfn.LET(_xlpm.events, _xlfn._xlws.FILTER(Plan[Activity],Plan[Date]=Calc!Z14), _xlpm.ic, _xlfn.XLOOKUP(_xlfn._xlws.FILTER(Plan[Type], Plan[Date]=Z14,"x"), icons[Type], icons[Icon]), _xlfn.TEXTJOIN(CHAR(10),TRUE, _xlpm.ic&_xlpm.events)),"")} | AA32: {=IFERROR(_xlfn.LET(_xlpm.events, _xlfn._xlws.FILTER(Plan[Activity],Plan[Date]=Calc!AA14), _xlpm.ic, _xlfn.XLOOKUP(_xlfn._xlws.FILTER(Plan[Type], Plan[Date]=AA14,"x"), icons[Type], icons[Icon]), _xlfn.TEXTJOIN(CHAR(10),TRUE, _xlpm.ic&_xlpm.events)),"")} | AB32: {=IFERROR(_xlfn.LET(_xlpm.events, _xlfn._xlws.FILTER(Plan[Activity],Plan[Date]=Calc!AB14), _xlpm.ic, _xlfn.XLOOKUP(_xlfn._xlws.FILTER(Plan[Type], Plan[Date]=AB14,"x"), icons[Type], icons[Icon]), _xlfn.TEXTJOIN(CHAR(10),TRUE, _xlpm.ic&_xlpm.events)),"")} | AC32: {=IFERROR(_xlfn.LET(_xlpm.events, _xlfn._xlws.FILTER(Plan[Activity],Plan[Date]=Calc!AC14), _xlpm.ic, _xlfn.XLOOKUP(_xlfn._xlws.FILTER(Plan[Type], Plan[Date]=AC14,"x"), icons[Type], icons[Icon]), _xlfn.TEXTJOIN(CHAR(10),TRUE, _xlpm.ic&_xlpm.events)),"")} | AD32: {=IFERROR(_xlfn.LET(_xlpm.events, _xlfn._xlws.FILTER(Plan[Activity],Plan[Date]=Calc!AD14), _xlpm.ic, _xlfn.XLOOKUP(_xlfn._xlws.FILTER(Plan[Type], Plan[Date]=AD14,"x"), icons[Type], icons[Icon]), _xlfn.TEXTJOIN(CHAR(10),TRUE, _xlpm.ic&_xlpm.events)),"")} | AE32: {=IFERROR(_xlfn.LET(_xlpm.events, _xlfn._xlws.FILTER(Plan[Activity],Plan[Date]=Calc!AE14), _xlpm.ic, _xlfn.XLOOKUP(_xlfn._xlws.FILTER(Plan[Type], Plan[Date]=AE14,"x"), icons[Type], icons[Icon]), _xlfn.TEXTJOIN(CHAR(10),TRUE, _xlpm.ic&_xlpm.events)),"")} | AF32: {=IFERROR(_xlfn.LET(_xlpm.events, _xlfn._xlws.FILTER(Plan[Activity],Plan[Date]=Calc!AF14), _xlpm.ic, _xlfn.XLOOKUP(_xlfn._xlws.FILTER(Plan[Type], Plan[Date]=AF14,"x"), icons[Type], icons[Icon]), _xlfn.TEXTJOIN(CHAR(10),TRUE, _xlpm.ic&_xlpm.events)),"")} | AJ32: #NAME? | AK32: #NAME? | AL32: #NAME? | AM32: #NAME? | AN32: #NAME? | AO32: #NAME? | AP32: #NAME? | AS32: #NAME? | AT32: #NAME? | AU32: #NAME? | AV32: #NAME? | AW32: #NAME? | AX32: #NAME? | AY32: #NAME?
C33: =C32 -> 4 | D33: #NAME? | E33: #NAME? | F33: #NAME? | G33: #NAME? | H33: #NAME? | I33: #NAME? | J33: #NAME? | K33: =WEEKNUM(D33,10+week.start) -> #NAME? | R33: =_xlfn.XLOOKUP(P33,icons[Type],icons[Icon],"") | S33: =IF(N33=0,"",TEXT(N33,"d-mmm")&": "&O33) | Z33: {=IFERROR(_xlfn.LET(_xlpm.events, _xlfn._xlws.FILTER(Plan[Activity],Plan[Date]=Calc!Z15), _xlpm.ic, _xlfn.XLOOKUP(_xlfn._xlws.FILTER(Plan[Type], Plan[Date]=Z15,"x"), icons[Type], icons[Icon]), _xlfn.TEXTJOIN(CHAR(10),TRUE, _xlpm.ic&_xlpm.events)),"")} | AA33: {=IFERROR(_xlfn.LET(_xlpm.events, _xlfn._xlws.FILTER(Plan[Activity],Plan[Date]=Calc!AA15), _xlpm.ic, _xlfn.XLOOKUP(_xlfn._xlws.FILTER(Plan[Type], Plan[Date]=AA15,"x"), icons[Type], icons[Icon]), _xlfn.TEXTJOIN(CHAR(10),TRUE, _xlpm.ic&_xlpm.events)),"")} | AB33: {=IFERROR(_xlfn.LET(_xlpm.events, _xlfn._xlws.FILTER(Plan[Activity],Plan[Date]=Calc!AB15), _xlpm.ic, _xlfn.XLOOKUP(_xlfn._xlws.FILTER(Plan[Type], Plan[Date]=AB15,"x"), icons[Type], icons[Icon]), _xlfn.TEXTJOIN(CHAR(10),TRUE, _xlpm.ic&_xlpm.events)),"")} | AC33: {=IFERROR(_xlfn.LET(_xlpm.events, _xlfn._xlws.FILTER(Plan[Activity],Plan[Date]=Calc!AC15), _xlpm.ic, _xlfn.XLOOKUP(_xlfn._xlws.FILTER(Plan[Type], Plan[Date]=AC15,"x"), icons[Type], icons[Icon]), _xlfn.TEXTJOIN(CHAR(10),TRUE, _xlpm.ic&_xlpm.events)),"")} | AD33: {=IFERROR(_xlfn.LET(_xlpm.events, _xlfn._xlws.FILTER(Plan[Activity],Plan[Date]=Calc!AD15), _xlpm.ic, _xlfn.XLOOKUP(_xlfn._xlws.FILTER(Plan[Type], Plan[Date]=AD15,"x"), icons[Type], icons[Icon]), _xlfn.TEXTJOIN(CHAR(10),TRUE, _xlpm.ic&_xlpm.events)),"")} | AE33: {=IFERROR(_xlfn.LET(_xlpm.events, _xlfn._xlws.FILTER(Plan[Activity],Plan[Date]=Calc!AE15), _xlpm.ic, _xlfn.XLOOKUP(_xlfn._xlws.FILTER(Plan[Type], Plan[Date]=AE15,"x"), icons[Type], icons[Icon]), _xlfn.TEXTJOIN(CHAR(10),TRUE, _xlpm.ic&_xlpm.events)),"")} | AF33: {=IFERROR(_xlfn.LET(_xlpm.events, _xlfn._xlws.FILTER(Plan[Activity],Plan[Date]=Calc!AF15), _xlpm.ic, _xlfn.XLOOKUP(_xlfn._xlws.FILTER(Plan[Type], Plan[Date]=AF15,"x"), icons[Type], icons[Icon]), _xlfn.TEXTJOIN(CHAR(10),TRUE, _xlpm.ic&_xlpm.events)),"")} | AJ33: #NAME? | AK33: #NAME? | AL33: #NAME? | AM33: #NAME? | AN33: #NAME? | AO33: #NAME? | AP33: #NAME? | AS33: #NAME? | AT33: #NAME? | AU33: #NAME? | AV33: #NAME? | AW33: #NAME? | AX33: #NAME? | AY33: #NAME?
C34: =C33 -> 4 | D34: #NAME? | E34: #NAME? | F34: #NAME? | G34: #NAME? | H34: #NAME? | I34: #NAME? | J34: #NAME? | K34: =WEEKNUM(D34,10+week.start) -> #NAME? | R34: =_xlfn.XLOOKUP(P34,icons[Type],icons[Icon],"") | S34: =IF(N34=0,"",TEXT(N34,"d-mmm")&": "&O34) | Z34: {=IFERROR(_xlfn.LET(_xlpm.events, _xlfn._xlws.FILTER(Plan[Activity],Plan[Date]=Calc!Z16), _xlpm.ic, _xlfn.XLOOKUP(_xlfn._xlws.FILTER(Plan[Type], Plan[Date]=Z16,"x"), icons[Type], icons[Icon]), _xlfn.TEXTJOIN(CHAR(10),TRUE, _xlpm.ic&_xlpm.events)),"")} | AA34: {=IFERROR(_xlfn.LET(_xlpm.events, _xlfn._xlws.FILTER(Plan[Activity],Plan[Date]=Calc!AA16), _xlpm.ic, _xlfn.XLOOKUP(_xlfn._xlws.FILTER(Plan[Type], Plan[Date]=AA16,"x"), icons[Type], icons[Icon]), _xlfn.TEXTJOIN(CHAR(10),TRUE, _xlpm.ic&_xlpm.events)),"")} | AB34: {=IFERROR(_xlfn.LET(_xlpm.events, _xlfn._xlws.FILTER(Plan[Activity],Plan[Date]=Calc!AB16), _xlpm.ic, _xlfn.XLOOKUP(_xlfn._xlws.FILTER(Plan[Type], Plan[Date]=AB16,"x"), icons[Type], icons[Icon]), _xlfn.TEXTJOIN(CHAR(10),TRUE, _xlpm.ic&_xlpm.events)),"")} | AC34: {=IFERROR(_xlfn.LET(_xlpm.events, _xlfn._xlws.FILTER(Plan[Activity],Plan[Date]=Calc!AC16), _xlpm.ic, _xlfn.XLOOKUP(_xlfn._xlws.FILTER(Plan[Type], Plan[Date]=AC16,"x"), icons[Type], icons[Icon]), _xlfn.TEXTJOIN(CHAR(10),TRUE, _xlpm.ic&_xlpm.events)),"")} | AD34: {=IFERROR(_xlfn.LET(_xlpm.events, _xlfn._xlws.FILTER(Plan[Activity],Plan[Date]=Calc!AD16), _xlpm.ic, _xlfn.XLOOKUP(_xlfn._xlws.FILTER(Plan[Type], Plan[Date]=AD16,"x"), icons[Type], icons[Icon]), _xlfn.TEXTJOIN(CHAR(10),TRUE, _xlpm.ic&_xlpm.events)),"")} | AE34: {=IFERROR(_xlfn.LET(_xlpm.events, _xlfn._xlws.FILTER(Plan[Activity],Plan[Date]=Calc!AE16), _xlpm.ic, _xlfn.XLOOKUP(_xlfn._xlws.FILTER(Plan[Type], Plan[Date]=AE16,"x"), icons[Type], icons[Icon]), _xlfn.TEXTJOIN(CHAR(10),TRUE, _xlpm.ic&_xlpm.events)),"")} | AF34: {=IFERROR(_xlfn.LET(_xlpm.events, _xlfn._xlws.FILTER(Plan[Activity],Plan[Date]=Calc!AF16), _xlpm.ic, _xlfn.XLOOKUP(_xlfn._xlws.FILTER(Plan[Type], Plan[Date]=AF16,"x"), icons[Type], icons[Icon]), _xlfn.TEXTJOIN(CHAR(10),TRUE, _xlpm.ic&_xlpm.events)),"")} | AJ34: #NAME? | AK34: #NAME? | AL34: #NAME? | AM34: #NAME? | AN34: #NAME? | AO34: #NAME? | AP34: #NAME? | AS34: #NAME? | AT34: #NAME? | AU34: #NAME? | AV34: #NAME? | AW34: #NAME? | AX34: #NAME? | AY34: #NAME?
C35: =C34 -> 4 | D35: #NAME? | E35: #NAME? | F35: #NAME? | G35: #NAME? | H35: #NAME? | I35: #NAME? | J35: #NAME? | K35: =WEEKNUM(D35,10+week.start) -> #NAME? | R35: =_xlfn.XLOOKUP(P35,icons[Type],icons[Icon],"") | S35: =IF(N35=0,"",TEXT(N35,"d-mmm")&": "&O35) | Z35: {=IFERROR(_xlfn.LET(_xlpm.events, _xlfn._xlws.FILTER(Plan[Activity],Plan[Date]=Calc!Z17), _xlpm.ic, _xlfn.XLOOKUP(_xlfn._xlws.FILTER(Plan[Type], Plan[Date]=Z17,"x"), icons[Type], icons[Icon]), _xlfn.TEXTJOIN(CHAR(10),TRUE, _xlpm.ic&_xlpm.events)),"")} | AA35: {=IFERROR(_xlfn.LET(_xlpm.events, _xlfn._xlws.FILTER(Plan[Activity],Plan[Date]=Calc!AA17), _xlpm.ic, _xlfn.XLOOKUP(_xlfn._xlws.FILTER(Plan[Type], Plan[Date]=AA17,"x"), icons[Type], icons[Icon]), _xlfn.TEXTJOIN(CHAR(10),TRUE, _xlpm.ic&_xlpm.events)),"")} | AB35: {=IFERROR(_xlfn.LET(_xlpm.events, _xlfn._xlws.FILTER(Plan[Activity],Plan[Date]=Calc!AB17), _xlpm.ic, _xlfn.XLOOKUP(_xlfn._xlws.FILTER(Plan[Type], Plan[Date]=AB17,"x"), icons[Type], icons[Icon]), _xlfn.TEXTJOIN(CHAR(10),TRUE, _xlpm.ic&_xlpm.events)),"")} | AC35: {=IFERROR(_xlfn.LET(_xlpm.events, _xlfn._xlws.FILTER(Plan[Activity],Plan[Date]=Calc!AC17), _xlpm.ic, _xlfn.XLOOKUP(_xlfn._xlws.FILTER(Plan[Type], Plan[Date]=AC17,"x"), icons[Type], icons[Icon]), _xlfn.TEXTJOIN(CHAR(10),TRUE, _xlpm.ic&_xlpm.events)),"")} | AD35: {=IFERROR(_xlfn.LET(_xlpm.events, _xlfn._xlws.FILTER(Plan[Activity],Plan[Date]=Calc!AD17), _xlpm.ic, _xlfn.XLOOKUP(_xlfn._xlws.FILTER(Plan[Type], Plan[Date]=AD17,"x"), icons[Type], icons[Icon]), _xlfn.TEXTJOIN(CHAR(10),TRUE, _xlpm.ic&_xlpm.events)),"")} | AE35: {=IFERROR(_xlfn.LET(_xlpm.events, _xlfn._xlws.FILTER(Plan[Activity],Plan[Date]=Calc!AE17), _xlpm.ic, _xlfn.XLOOKUP(_xlfn._xlws.FILTER(Plan[Type], Plan[Date]=AE17,"x"), icons[Type], icons[Icon]), _xlfn.TEXTJOIN(CHAR(10),TRUE, _xlpm.ic&_xlpm.events)),"")} | AF35: {=IFERROR(_xlfn.LET(_xlpm.events, _xlfn._xlws.FILTER(Plan[Activity],Plan[Date]=Calc!AF17), _xlpm.ic, _xlfn.XLOOKUP(_xlfn._xlws.FILTER(Plan[Type], Plan[Date]=AF17,"x"), icons[Type], icons[Icon]), _xlfn.TEXTJOIN(CHAR(10),TRUE, _xlpm.ic&_xlpm.events)),"")} | AS35: #NAME? | AT35: #NAME? | AU35: #NAME? | AV35: #NAME? | AW35: #NAME? | AX35: #NAME? | AY35: #NAME?
C36: =C35 -> 4 | D36: #NAME? | E36: #NAME? | F36: #NAME? | G36: #NAME? | H36: #NAME? | I36: #NAME? | J36: #NAME? | K36: =WEEKNUM(D36,10+week.start) -> #NAME? | R36: =_xlfn.XLOOKUP(P36,icons[Type],icons[Icon],"") | S36: =IF(N36=0,"",TEXT(N36,"d-mmm")&": "&O36) | Z36: {=IFERROR(_xlfn.LET(_xlpm.events, _xlfn._xlws.FILTER(Plan[Activity],Plan[Date]=Calc!Z18), _xlpm.ic, _xlfn.XLOOKUP(_xlfn._xlws.FILTER(Plan[Type], Plan[Date]=Z18,"x"), icons[Type], icons[Icon]), _xlfn.TEXTJOIN(CHAR(10),TRUE, _xlpm.ic&_xlpm.events)),"")} | AA36: {=IFERROR(_xlfn.LET(_xlpm.events, _xlfn._xlws.FILTER(Plan[Activity],Plan[Date]=Calc!AA18), _xlpm.ic, _xlfn.XLOOKUP(_xlfn._xlws.FILTER(Plan[Type], Plan[Date]=AA18,"x"), icons[Type], icons[Icon]), _xlfn.TEXTJOIN(CHAR(10),TRUE, _xlpm.ic&_xlpm.events)),"")} | AB36: {=IFERROR(_xlfn.LET(_xlpm.events, _xlfn._xlws.FILTER(Plan[Activity],Plan[Date]=Calc!AB18), _xlpm.ic, _xlfn.XLOOKUP(_xlfn._xlws.FILTER(Plan[Type], Plan[Date]=AB18,"x"), icons[Type], icons[Icon]), _xlfn.TEXTJOIN(CHAR(10),TRUE, _xlpm.ic&_xlpm.events)),"")} | AC36: {=IFERROR(_xlfn.LET(_xlpm.events, _xlfn._xlws.FILTER(Plan[Activity],Plan[Date]=Calc!AC18), _xlpm.ic, _xlfn.XLOOKUP(_xlfn._xlws.FILTER(Plan[Type], Plan[Date]=AC18,"x"), icons[Type], icons[Icon]), _xlfn.TEXTJOIN(CHAR(10),TRUE, _xlpm.ic&_xlpm.events)),"")} | AD36: {=IFERROR(_xlfn.LET(_xlpm.events, _xlfn._xlws.FILTER(Plan[Activity],Plan[Date]=Calc!AD18), _xlpm.ic, _xlfn.XLOOKUP(_xlfn._xlws.FILTER(Plan[Type], Plan[Date]=AD18,"x"), icons[Type], icons[Icon]), _xlfn.TEXTJOIN(CHAR(10),TRUE, _xlpm.ic&_xlpm.events)),"")} | AE36: {=IFERROR(_xlfn.LET(_xlpm.events, _xlfn._xlws.FILTER(Plan[Activity],Plan[Date]=Calc!AE18), _xlpm.ic, _xlfn.XLOOKUP(_xlfn._xlws.FILTER(Plan[Type], Plan[Date]=AE18,"x"), icons[Type], icons[Icon]), _xlfn.TEXTJOIN(CHAR(10),TRUE, _xlpm.ic&_xlpm.events)),"")} | AF36: {=IFERROR(_xlfn.LET(_xlpm.events, _xlfn._xlws.FILTER(Plan[Activity],Plan[Date]=Calc!AF18), _xlpm.ic, _xlfn.XLOOKUP(_xlfn._xlws.FILTER(Plan[Type], Plan[Date]=AF18,"x"), icons[Type], icons[Icon]), _xlfn.TEXTJOIN(CHAR(10),TRUE, _xlpm.ic&_xlpm.events)),"")} | AS36: #NAME? | AT36: #NAME? | AU36: #NAME? | AV36: #NAME? | AW36: #NAME? | AX36: #NAME? | AY36: #NAME?
C37: =C31+1 -> 5 | D37: {=_xlfn.LET(_xlpm.mStart, DATE(cal.year, C37, 1), _xlpm.wDay, WEEKDAY(_xlpm.mStart, 10+week.start), _xlfn.SEQUENCE(6,7,_xlpm.mStart-_xlpm.wDay+1))} -> #NAME? | E37: #NAME? | F37: #NAME? | G37: #NAME? | H37: #NAME? | I37: #NAME? | J37: #NAME? | K37: =WEEKNUM(D37,10+week.start) -> #NAME? | R37: =_xlfn.XLOOKUP(P37,icons[Type],icons[Icon],"") | S37: =IF(N37=0,"",TEXT(N37,"d-mmm")&": "&O37) | AJ37: {=_xlfn.MAP(_xlfn.ANCHORARRAY(AJ29), _xlfn.LAMBDA(_xlpm.a, IFERROR(_xlfn.LET(_xlpm.events, _xlfn._xlws.FILTER(Plan[Activity],Plan[Date]=_xlpm.a), _xlpm.ic, _xlfn.XLOOKUP(_xlfn._xlws.FILTER(Plan[Type], Plan[Date]=_xlpm.a,"x"), icons[Type], icons[Icon]), _xlfn.TEXTJOIN(CHAR(10),TRUE, _xlpm.ic&_xlpm.events)),"")))} -> #NAME? | AK37: #NAME? | AL37: #NAME? | AM37: #NAME? | AN37: #NAME? | AO37: #NAME? | AP37: #NAME? | AS37: #NAME? | AT37: #NAME? | AU37: #NAME? | AV37: #NAME? | AW37: #NAME? | AX37: #NAME? | AY37: #NAME?
C38: =C37 -> 5 | D38: #NAME? | E38: #NAME? | F38: #NAME? | G38: #NAME? | H38: #NAME? | I38: #NAME? | J38: #NAME? | K38: =WEEKNUM(D38,10+week.start) -> #NAME? | AJ38: #NAME? | AK38: #NAME? | AL38: #NAME? | AM38: #NAME? | AN38: #NAME? | AO38: #NAME? | AP38: #NAME? | AS38: #NAME? | AT38: #NAME? | AU38: #NAME? | AV38: #NAME? | AW38: #NAME? | AX38: #NAME? | AY38: #NAME?
C39: =C38 -> 5 | D39: #NAME? | E39: #NAME? | F39: #NAME? | G39: #NAME? | H39: #NAME? | I39: #NAME? | J39: #NAME? | K39: =WEEKNUM(D39,10+week.start) -> #NAME? | AJ39: #NAME? | AK39: #NAME? | AL39: #NAME? | AM39: #NAME? | AN39: #NAME? | AO39: #NAME? | AP39: #NAME? | AS39: #NAME? | AT39: #NAME? | AU39: #NAME? | AV39: #NAME? | AW39: #NAME? | AX39: #NAME? | AY39: #NAME?
C40: =C39 -> 5 | D40: #NAME? | E40: #NAME? | F40: #NAME? | G40: #NAME? | H40: #NAME? | I40: #NAME? | J40: #NAME? | K40: =WEEKNUM(D40,10+week.start) -> #NAME? | AJ40: #NAME? | AK40: #NAME? | AL40: #NAME? | AM40: #NAME? | AN40: #NAME? | AO40: #NAME? | AP40: #NAME? | AS40: #NAME? | AT40: #NAME? | AU40: #NAME? | AV40: #NAME? | AW40: #NAME? | AX40: #NAME? | AY40: #NAME?
C41: =C40 -> 5 | D41: #NAME? | E41: #NAME? | F41: #NAME? | G41: #NAME? | H41: #NAME? | I41: #NAME? | J41: #NAME? | K41: =WEEKNUM(D41,10+week.start) -> #NAME? | AJ41: #NAME? | AK41: #NAME? | AL41: #NAME? | AM41: #NAME? | AN41: #NAME? | AO41: #NAME? | AP41: #NAME?
C42: =C41 -> 5 | D42: #NAME? | E42: #NAME? | F42: #NAME? | G42: #NAME? | H42: #NAME? | I42: #NAME? | J42: #NAME? | K42: =WEEKNUM(D42,10+week.start) -> #NAME? | AJ42: #NAME? | AK42: #NAME? | AL42: #NAME? | AM42: #NAME? | AN42: #NAME? | AO42: #NAME? | AP42: #NAME?
C43: =C37+1 -> 6 | D43: {=_xlfn.LET(_xlpm.mStart, DATE(cal.year, C43, 1), _xlpm.wDay, WEEKDAY(_xlpm.mStart, 10+week.start), _xlfn.SEQUENCE(6,7,_xlpm.mStart-_xlpm.wDay+1))} -> #NAME? | E43: #NAME? | F43: #NAME? | G43: #NAME? | H43: #NAME? | I43: #NAME? | J43: #NAME? | K43: =WEEKNUM(D43,10+week.start) -> #NAME?
C44: =C43 -> 6 | D44: #NAME? | E44: #NAME? | F44: #NAME? | G44: #NAME? | H44: #NAME? | I44: #NAME? | J44: #NAME? | K44: =WEEKNUM(D44,10+week.start) -> #NAME?
C45: =C44 -> 6 | D45: #NAME? | E45: #NAME? | F45: #NAME? | G45: #NAME? | H45: #NAME? | I45: #NAME? | J45: #NAME? | K45: =WEEKNUM(D45,10+week.start) -> #NAME? | AI45: =AI29+1 -> 3 | AJ45: {=_xlfn.LET(_xlpm.dt, _xlfn._xlws.FILTER(monthly.calendar, month.nums=AI45), IF(MONTH(_xlpm.dt)<>AI45,"",_xlpm.dt))} -> #NAME? | AK45: #NAME? | AL45: #NAME? | AM45: #NAME? | AN45: #NAME? | AO45: #NAME? | AP45: #NAME? | AS45: {=_xlfn.WRAPROWS(_xlfn.TOCOL(_xlfn.HSTACK(_xlfn.ANCHORARRAY(AJ45),_xlfn.ANCHORARRAY(AJ53))),7)} -> #NAME? | AT45: #NAME? | AU45: #NAME? | AV45: #NAME? | AW45: #NAME? | AX45: #NAME? | AY45: #NAME?
C46: =C45 -> 6 | D46: #NAME? | E46: #NAME? | F46: #NAME? | G46: #NAME? | H46: #NAME? | I46: #NAME? | J46: #NAME? | K46: =WEEKNUM(D46,10+week.start) -> #NAME? | AJ46: #NAME? | AK46: #NAME? | AL46: #NAME? | AM46: #NAME? | AN46: #NAME? | AO46: #NAME? | AP46: #NAME? | AS46: #NAME? | AT46: #NAME? | AU46: #NAME? | AV46: #NAME? | AW46: #NAME? | AX46: #NAME? | AY46: #NAME?
C47: =C46 -> 6 | D47: #NAME? | E47: #NAME? | F47: #NAME? | G47: #NAME? | H47: #NAME? | I47: #NAME? | J47: #NAME? | K47: =WEEKNUM(D47,10+week.start) -> #NAME? | AJ47: #NAME? | AK47: #NAME? | AL47: #NAME? | AM47: #NAME? | AN47: #NAME? | AO47: #NAME? | AP47: #NAME? | AS47: #NAME? | AT47: #NAME? | AU47: #NAME? | AV47: #NAME? | AW47: #NAME? | AX47: #NAME? | AY47: #NAME?
...
